#VRML_SIM R2021a utf8
WorldInfo {
  basicTimeStep 16
  coordinateSystem "NUE"
  contactProperties [
    ContactProperties {
      material2 "slippy"
      coulombFriction [
        0
      ]
    }
    ContactProperties {
      material2 "block"
      coulombFriction [
        0.01
      ]
    }
  ]
}
Viewpoint {
  orientation -0.194753686543591 -0.9599547755815605 -0.2013897475440012 1.9272635712719994
  position -3.4147099914986345 1.6807147732580354 -1.043178718666688
}
TexturedBackground {
}
TexturedBackgroundLight {
}
Floor {
  size 2.4 2.4
  appearance Asphalt {
  }
}
DEF Block_R1 Solid {
  translation 1.00934 0.05 -0.406061
  children [
    DEF BOX_R Shape {
      appearance PBRAppearance {
        baseColor 1 0 0
        metalness 0
      }
      geometry Box {
        size 0.1 0.1 0.1
      }
    }
  ]
  name "solid(4)"
  contactMaterial "box"
  boundingObject USE BOX_R
  physics Physics {
  }
}
DEF Block_R2 Solid {
  translation 0.496365 0.05 1.05927
  children [
    USE BOX_R
  ]
  name "solid(13)"
  contactMaterial "block"
  boundingObject USE BOX_R
  physics Physics {
  }
}
DEF Block_R3 Solid {
  translation 1.02666 0.05 -0.0767087
  children [
    USE BOX_R
  ]
  name "solid(12)"
  boundingObject USE BOX_R
  physics Physics {
  }
}
DEF Block_R4 Solid {
  translation 0.908588 0.05 0.113184
  children [
    USE BOX_R
  ]
  name "solid(7)"
  boundingObject USE BOX_R
  physics Physics {
  }
}
DEF Block_B1 Solid {
  translation -1.1 0.05 1
  children [
    DEF BOX_B Shape {
      appearance PBRAppearance {
        baseColor 0 0 1
        metalness 0
      }
      geometry Box {
        size 0.05 0.05 0.05
      }
    }
  ]
  name "solid(8)"
  boundingObject USE BOX_B
  physics Physics {
  }
}
DEF Block_B2 Solid {
  translation 0.848253 0.05 -0.0512545
  children [
    USE BOX_B
  ]
  name "solid(9)"
  boundingObject USE BOX_B
  physics Physics {
  }
}
DEF Block_B3 Solid {
  translation 1.08601 0.05 0.122335
  children [
    USE BOX_B
  ]
  name "solid(10)"
  boundingObject USE BOX_B
  physics Physics {
  }
}
DEF Block_B4 Solid {
  translation 1 0.05 0.7
  children [
    USE BOX_B
  ]
  name "solid(11)"
  boundingObject USE BOX_B
  physics Physics {
  }
}
DEF Floor_colour Solid {
  translation 1 0.0001 1
  children [
    Shape {
      appearance PBRAppearance {
        baseColor 1 0 0
      }
      geometry Plane {
        size 0.4 0.4
      }
    }
  ]
  name "solid(6)"
}
DEF Floor_colour Solid {
  translation 1 0.0001 -1
  children [
    Shape {
      appearance PBRAppearance {
        baseColor 0 0 1
      }
      geometry Plane {
        size 0.4 0.4
      }
    }
  ]
  name "solid(5)"
}
DEF WALL_1 Solid {
  translation 1.2 0.05 0
  children [
    DEF WALL_SHAPE Shape {
      appearance PBRAppearance {
        baseColor 0.12549 0.368627 0.729412
        roughness 1
        metalness 0
      }
      geometry Box {
        size 0.02 0.1 2.38
      }
    }
  ]
  boundingObject USE WALL_SHAPE
}
DEF WALL_2 Solid {
  translation -1.2 0.05 0
  children [
    USE WALL_SHAPE
  ]
  name "solid(1)"
  boundingObject USE WALL_SHAPE
}
DEF WALL_3 Solid {
  translation 0 0.05 -1.2
  rotation 0 1 0 1.5708
  children [
    USE WALL_SHAPE
  ]
  name "solid(2)"
  boundingObject USE WALL_SHAPE
}
DEF WALL_4 Solid {
  translation 0 0.05 1.2
  rotation 0 1 0 1.5708
  children [
    USE WALL_SHAPE
  ]
  name "solid(3)"
  boundingObject USE WALL_SHAPE
}
Robot {
  translation 1 0 -1
  rotation 0 1 0 -1.5707996938995747
  children [
    Camera {
      translation 0 0.025 0.1
    }
    Solid {
      translation 0 -0.03 0
      children [
        Shape {
          appearance PBRAppearance {
            baseColor 0 0 0
          }
          geometry DEF CASTOR_BALL Sphere {
            radius 0.01
          }
        }
      ]
      name "solid(2)"
      contactMaterial "slippy"
      boundingObject USE CASTOR_BALL
      physics Physics {
      }
    }
    DEF BODY Shape {
      appearance PBRAppearance {
        baseColor 0 0.5 1
        metalness 0
      }
      geometry Box {
        size 0.1 0.05 0.2
      }
    }
    DEF WHEEL1 HingeJoint {
      jointParameters HingeJointParameters {
        anchor 0.06 0 0.05
      }
      device [
        RotationalMotor {
          name "wheel1"
          maxTorque 100
        }
      ]
      endPoint Solid {
        translation 0.06 0 0.05
        rotation 0 0 1 1.5707963071795863
        children [
          DEF WHEEL Shape {
            appearance PBRAppearance {
              baseColor 0.305882 0.898039 0.250981
              roughness 1
              metalness 0
            }
            geometry Cylinder {
              height 0.02
              radius 0.04
              subdivision 24
            }
          }
        ]
        boundingObject USE WHEEL
        physics Physics {
        }
      }
    }
    DEF WHEEL2 HingeJoint {
      jointParameters HingeJointParameters {
        anchor -0.06 0 0.05
      }
      device [
        RotationalMotor {
          name "wheel2"
          maxTorque 100
        }
      ]
      endPoint Solid {
        translation -0.06 0 0.05
        rotation 0 0 -1 1.5707963271795862
        children [
          USE WHEEL
        ]
        name "solid(1)"
        boundingObject USE WHEEL
        physics Physics {
        }
      }
    }
    DEF DS_RIGHT DistanceSensor {
      translation -0.03 0.025 0.1
      rotation 0 1 0 -1.5708
      children [
        Shape {
          appearance PBRAppearance {
            baseColor 1 0 1
            metalness 0
          }
          geometry Box {
            size 0.01 0.01 0.01
          }
        }
      ]
      name "ds_right"
    }
    DEF DS_LEFT DistanceSensor {
      translation 0.03 0.025 0.1
      rotation 0 1 0 -1.5709
      children [
        Shape {
          appearance PBRAppearance {
            baseColor 1 0 1
            roughness 1
            metalness 0
          }
          geometry Box {
            size 0.01 0.01 0.01
          }
        }
      ]
      name "ds_left"
    }
    Solid {
      translation 0.0475 -0.02 0.125
      children [
        Shape {
          appearance PBRAppearance {
            baseColor 0 0.5 1
            metalness 0
          }
          geometry DEF ARM Box {
            size 0.005 0.03 0.05
          }
        }
      ]
      name "solid(3)"
      boundingObject USE ARM
      physics Physics {
      }
    }
    Solid {
      translation -0.0475 -0.02 0.125
      children [
        Shape {
          appearance PBRAppearance {
            baseColor 0 0.5 1
            metalness 0
          }
          geometry USE ARM
        }
      ]
      name "solid(4)"
      boundingObject USE ARM
      physics Physics {
      }
    }
    Compass {
      translation 0 0.025 0.1
    }
    GPS {
      translation 0 0.025 0.1
    }
    Emitter {
      translation 0 0.025 0.1
    }
    Receiver {
      translation 0 0.025 0.1
    }
  ]
  name "robot(1)"
  boundingObject USE BODY
  physics Physics {
  }
}
Robot {
  translation 1 0 1
  rotation 0 1 0 -1.5707996938995747
  children [
    Camera {
      translation 0 0.025 0.1
    }
    Solid {
      translation 0 -0.03 0
      children [
        Shape {
          appearance PBRAppearance {
            baseColor 0 0 0
          }
          geometry DEF CASTOR_BALL Sphere {
            radius 0.01
          }
        }
      ]
      name "solid(2)"
      contactMaterial "slippy"
      boundingObject USE CASTOR_BALL
      physics Physics {
      }
    }
    DEF BODY Shape {
      appearance PBRAppearance {
        baseColor 0 0.5 1
        metalness 0
      }
      geometry Box {
        size 0.1 0.05 0.2
      }
    }
    DEF WHEEL1 HingeJoint {
      jointParameters HingeJointParameters {
        anchor 0.06 0 0.05
      }
      device [
        RotationalMotor {
          name "wheel1"
          maxTorque 100
        }
      ]
      endPoint Solid {
        translation 0.060061096231712297 -6.023306508778913e-05 0.049973930669938375
        rotation -0.0008004404636122508 0.0014088583283205132 0.9999986872057759 1.570898955933666
        children [
          DEF WHEEL Shape {
            appearance PBRAppearance {
              baseColor 0.305882 0.898039 0.250981
              roughness 1
              metalness 0
            }
            geometry Cylinder {
              height 0.02
              radius 0.04
              subdivision 24
            }
          }
        ]
        boundingObject USE WHEEL
        physics Physics {
        }
      }
    }
    DEF WHEEL2 HingeJoint {
      jointParameters HingeJointParameters {
        anchor -0.06 0 0.05
      }
      device [
        RotationalMotor {
          name "wheel2"
          maxTorque 100
        }
      ]
      endPoint Solid {
        translation -0.060076793877242296 -3.720246855932564e-05 0.05002516694116893
        rotation -0.0006167589520926097 -0.0017728202341673034 -0.9999982383568545 1.5702551333129804
        children [
          USE WHEEL
        ]
        name "solid(1)"
        boundingObject USE WHEEL
        physics Physics {
        }
      }
    }
    DEF DS_RIGHT DistanceSensor {
      translation -0.03 0.025 0.1
      rotation 0 1 0 -1.5708
      children [
        Shape {
          appearance PBRAppearance {
            baseColor 1 0 1
            metalness 0
          }
          geometry Box {
            size 0.01 0.01 0.01
          }
        }
      ]
      name "ds_right"
      lookupTable [
        0 0 0
        0.5 1000 0
      ]
    }
    DEF DS_LEFT DistanceSensor {
      translation 0.03 0.025 0.1
      rotation 0 1 0 -1.5709
      children [
        Shape {
          appearance PBRAppearance {
            baseColor 1 0 1
            roughness 1
            metalness 0
          }
          geometry Box {
            size 0.01 0.01 0.01
          }
        }
      ]
      name "ds_left"
      lookupTable [
        0 0 0
        0.5 1000 0
      ]
    }
    Solid {
      translation 0.0475 -0.02 0.125
      children [
        Shape {
          appearance PBRAppearance {
            baseColor 0 0.5 1
            metalness 0
          }
          geometry DEF ARM Box {
            size 0.005 0.03 0.05
          }
        }
      ]
      name "solid(3)"
      boundingObject USE ARM
      physics Physics {
      }
    }
    Solid {
      translation -0.0475 -0.02 0.125
      children [
        Shape {
          appearance PBRAppearance {
            baseColor 0 0.5 1
            metalness 0
          }
          geometry USE ARM
        }
      ]
      name "solid(4)"
      boundingObject USE ARM
      physics Physics {
      }
    }
    Compass {
      translation 0 0.025 0.1
      rotation 0 1 0 -1.5707996938995747
      yAxis FALSE
    }
    GPS {
      translation 0 0.025 0.1
    }
    Emitter {
      translation 0 0.025 0.1
    }
    Receiver {
      translation 0 0.025 0.1
    }
  ]
  name "robot(2)"
  boundingObject USE BODY
  physics Physics {
  }
  controller "preplannedpath"
}
