#VRML_SIM R2021a utf8
WorldInfo {
  basicTimeStep 16
  coordinateSystem "NUE"
  contactProperties [
    ContactProperties {
      material2 "slippy"
      coulombFriction [
        0
      ]
    }
    ContactProperties {
      material2 "block"
      coulombFriction [
        0.01
      ]
    }
  ]
}
Viewpoint {
  orientation -0.34417538900487404 -0.8807092334472848 -0.3254144245789355 1.743683451745449
  position -4.516258291739668 4.122029952211431 -0.26019440214135525
}
TexturedBackground {
}
TexturedBackgroundLight {
}
Floor {
  size 2.4 2.4
  appearance Asphalt {
  }
}
DEF Block_R1 Solid {
  translation -0.647764 0.05 0.641572
  children [
    DEF BOX_R Shape {
      appearance PBRAppearance {
        baseColor 1 0 0
        metalness 0
      }
      geometry Box {
        size 0.05 0.05 0.05
      }
    }
  ]
  name "solid(4)"
  contactMaterial "box"
  boundingObject USE BOX_R
  physics Physics {
  }
}
DEF Block_R2 Solid {
  translation -0.663997 0.05 0.287594
  children [
    DEF BOX_R Shape {
      appearance PBRAppearance {
        baseColor 1 0 0
        metalness 0
      }
      geometry Box {
        size 0.05 0.05 0.05
      }
    }
  ]
  name "solid(13)"
  boundingObject USE BOX_R
  physics Physics {
  }
}
DEF Block_R3 Solid {
  translation -0.00507102 0.05 1.05474
  children [
    USE BOX_R
  ]
  name "solid(12)"
  boundingObject USE BOX_R
  physics Physics {
  }
}
DEF Block_R4 Solid {
  translation -0.19014 0.05 0.6123
  children [
    USE BOX_R
  ]
  name "solid(7)"
  boundingObject USE BOX_R
  physics Physics {
  }
  recognitionColors [
    1 0 0
  ]
}
DEF Block_B1 Solid {
  translation 0.608877 0.05 0.988291
  children [
    DEF BOX_B Shape {
      appearance PBRAppearance {
        baseColor 0 0 1
        metalness 0
      }
      geometry Box {
        size 0.05 0.05 0.05
      }
    }
  ]
  name "solid(8)"
  boundingObject USE BOX_B
  physics Physics {
  }
}
DEF Block_B2 Solid {
  translation -0.859482 0.05 0.934953
  children [
    USE BOX_B
  ]
  name "solid(9)"
  boundingObject USE BOX_B
  physics Physics {
  }
}
DEF Block_B3 Solid {
  translation 0.849575 0.05 0.321547
  children [
    USE BOX_B
  ]
  name "solid(10)"
  boundingObject USE BOX_B
  physics Physics {
  }
}
DEF Block_B4 Solid {
  translation 0.260813 0.05 0.615649
  children [
    USE BOX_B
  ]
  name "solid(11)"
  boundingObject USE BOX_B
  physics Physics {
  }
}
DEF Floor_colour Solid {
  translation 1 0.0001 1
  children [
    Shape {
      appearance PBRAppearance {
        baseColor 1 0 0
      }
      geometry Plane {
        size 0.4 0.4
      }
    }
  ]
  name "solid(6)"
}
DEF Floor_colour Solid {
  translation 1 0.0001 -1
  children [
    Shape {
      appearance PBRAppearance {
        baseColor 0 0 1
      }
      geometry Plane {
        size 0.4 0.4
      }
    }
  ]
  name "solid(5)"
}
DEF WALL_1 Solid {
  translation 1.2 0.05 0
  children [
    DEF WALL_SHAPE Shape {
      appearance PBRAppearance {
        baseColor 0 0.333333 0
        roughness 1
        metalness 0
      }
      geometry Box {
        size 0.02 0.1 2.38
      }
    }
  ]
  boundingObject USE WALL_SHAPE
}
DEF WALL_2 Solid {
  translation -1.2 0.05 0
  children [
    USE WALL_SHAPE
  ]
  name "solid(1)"
  boundingObject USE WALL_SHAPE
}
DEF WALL_3 Solid {
  translation 0 0.05 -1.2
  rotation 0 1 0 1.5708
  children [
    USE WALL_SHAPE
  ]
  name "solid(2)"
  boundingObject USE WALL_SHAPE
}
DEF WALL_4 Solid {
  translation 0 0.05 1.2
  rotation 0 1 0 1.5708
  children [
    USE WALL_SHAPE
  ]
  name "solid(3)"
  boundingObject USE WALL_SHAPE
}
Robot {
  translation 0.822222 0.05 -1.41799
  rotation 0 1 0 -1.57
  children [
    Solid {
      translation 0 -0.03 -0.0665
      children [
        Shape {
          appearance PBRAppearance {
            baseColor 0 0 0
          }
          geometry DEF CASTOR_BALL Sphere {
            radius 0.01
          }
        }
      ]
      name "solid(2)"
      contactMaterial "slippy"
      boundingObject USE CASTOR_BALL
      physics Physics {
      }
    }
    DEF BODY Shape {
      appearance PBRAppearance {
        baseColor 0 0.5 1
        metalness 0
      }
      geometry Box {
        size 0.15 0.065 0.173
      }
    }
    Transform {
      translation 0.075 0 0.0865
      children [
        DEF WHEEL1 HingeJoint {
          jointParameters HingeJointParameters {
            anchor 0.015 -0.005 -0.04
          }
          device [
            RotationalMotor {
              name "wheel1"
              maxTorque 100
            }
          ]
          endPoint Solid {
            translation 0.015000000000000013 -0.0049999999999999906 -0.040000000000000036
            rotation 1.3066852210941824e-19 2.352525206868997e-16 0.9999999999999999 1.5707953071884027
            children [
              DEF WHEEL Shape {
                appearance PBRAppearance {
                }
                geometry Cylinder {
                  height 0.03
                  radius 0.035
                }
              }
            ]
            boundingObject USE WHEEL
            physics Physics {
            }
          }
        }
        DEF WHEEL2 HingeJoint {
          jointParameters HingeJointParameters {
            anchor -0.165 -0.005 -0.04
          }
          device [
            RotationalMotor {
              name "wheel2"
              maxTorque 100
            }
          ]
          endPoint Solid {
            translation -0.16500000000000015 -0.0049999999999999906 -0.039999999999999925
            rotation 7.86666717642209e-17 -2.6146818149334733e-19 1 1.57
            children [
              USE WHEEL
            ]
            name "solid(1)"
            boundingObject USE WHEEL
            physics Physics {
            }
          }
        }
        Solid {
          translation -0.006 -0.01 0.04
          children [
            DEF ARM Shape {
              appearance PBRAppearance {
              }
              geometry Box {
                size 0.012 0.05 0.08
              }
            }
          ]
          name "solid(3)"
          boundingObject USE ARM
          physics Physics {
          }
        }
        Solid {
          translation -0.144 -0.01 0.04
          children [
            USE ARM
          ]
          name "solid(4)"
          boundingObject USE ARM
          physics Physics {
          }
        }
        Solid {
          translation -0.075 0.015 0.04
          children [
            DEF LID Shape {
              appearance PBRAppearance {
              }
              geometry Box {
                size 0.126 0.001 0.08
              }
            }
          ]
          name "solid(5)"
          boundingObject USE LID
          physics Physics {
          }
        }
        DistanceSensor {
          translation -0.001 -0.015 0.08
          rotation 0 1 0 -2.61799
          children [
            DEF DS Shape {
              appearance PBRAppearance {
                baseColor 0 0 0
                metalness 0
              }
              geometry Box {
                size 0.01 0.01 0.01
              }
            }
          ]
          name "ds_left"
          lookupTable [
            0 0 0
            0.3 1000 0
          ]
        }
        DistanceSensor {
          translation -0.149 -0.015 0.08
          rotation 0 1 0 -0.5236
          children [
            USE DS
          ]
          name "ds_right"
          lookupTable [
            0 0 0
            0.3 1000 0
          ]
        }
        Camera {
          translation -0.1 -0.015 0
          rotation 0 1 0 3.14159
          children [
            USE DS
          ]
          name "camera_left"
          recognitionColors [
            0 0 0
          ]
          fieldOfView 0.7854
          width 1
          height 1
          far 0.1
        }
        Camera {
          translation -0.05 -0.015 0
          rotation 0 1 0 3.14159
          children [
            USE DS
          ]
          name "camera_right"
          recognitionColors [
            0 0 0
          ]
          fieldOfView 0.7854
          width 1
          height 1
          far 0.1
        }
        Emitter {
          translation -0.075 -0.015 0
        }
        Receiver {
          translation -0.075 -0.015 0
        }
        Compass {
          translation -0.075 -0.015 0
          rotation 0 1 0 -1.57
        }
        GPS {
          translation -0.075 -0.015 0
        }
      ]
    }
  ]
  name "HungryHippo2"
  boundingObject USE BODY
  physics Physics {
  }
  controller ""
  controllerArgs [
    ""
  ]
}
Robot {
  translation 1 0.05 1
  rotation 0 1 0 -1.57
  children [
    Solid {
      translation 0 -0.03 -0.0665
      children [
        Shape {
          appearance PBRAppearance {
            baseColor 0 0 0
          }
          geometry DEF CASTOR_BALL Sphere {
            radius 0.01
          }
        }
      ]
      name "solid(2)"
      contactMaterial "slippy"
      boundingObject USE CASTOR_BALL
      physics Physics {
      }
    }
    DEF BODY Shape {
      appearance PBRAppearance {
        baseColor 1 0 0
        metalness 0
      }
      geometry Box {
        size 0.15 0.065 0.173
      }
    }
    Transform {
      translation 0.075 0 0.0865
      children [
        DEF WHEEL1 HingeJoint {
          jointParameters HingeJointParameters {
            anchor 0.015 -0.005 -0.04
          }
          device [
            RotationalMotor {
              name "wheel1"
              maxTorque 100
            }
          ]
          endPoint Solid {
            translation 0.01499999999999968 -0.0049999999999999906 -0.040000000000000036
            rotation 1.5713999435949918e-16 2.352525206869009e-16 0.9999999999999999 1.5707953071883924
            children [
              DEF WHEEL Shape {
                appearance PBRAppearance {
                }
                geometry Cylinder {
                  height 0.03
                  radius 0.035
                }
              }
            ]
            boundingObject USE WHEEL
            physics Physics {
            }
          }
        }
        DEF WHEEL2 HingeJoint {
          jointParameters HingeJointParameters {
            anchor -0.165 -0.005 -0.04
          }
          device [
            RotationalMotor {
              name "wheel2"
              maxTorque 100
            }
          ]
          endPoint Solid {
            translation -0.16500000000000015 -0.0049999999999999906 -0.039999999999999925
            rotation -1.5694102614816144e-16 -1.5733326673979327e-16 1 1.5699999999999963
            children [
              USE WHEEL
            ]
            name "solid(1)"
            boundingObject USE WHEEL
            physics Physics {
            }
          }
        }
        Solid {
          translation -0.006 -0.01 0.04
          children [
            DEF ARM Shape {
              appearance PBRAppearance {
              }
              geometry Box {
                size 0.012 0.05 0.08
              }
            }
          ]
          name "solid(3)"
          boundingObject USE ARM
          physics Physics {
          }
        }
        Solid {
          translation -0.144 -0.01 0.04
          children [
            USE ARM
          ]
          name "solid(4)"
          boundingObject USE ARM
          physics Physics {
          }
        }
        Solid {
          translation -0.075 0.015 0.04
          children [
            DEF LID Shape {
              appearance PBRAppearance {
              }
              geometry Box {
                size 0.126 0.001 0.08
              }
            }
          ]
          name "solid(5)"
          boundingObject USE LID
          physics Physics {
          }
        }
        DistanceSensor {
          translation -0.001 -0.015 0.08
          rotation 0 1 0 -2.61799
          children [
            DEF DS Shape {
              appearance PBRAppearance {
                baseColor 0 0 0
                metalness 0
              }
              geometry Box {
                size 0.01 0.01 0.01
              }
            }
          ]
          name "ds_left"
          lookupTable [
            0 0 0
            0.3 1000 0
          ]
        }
        DistanceSensor {
          translation -0.149 -0.015 0.08
          rotation 0 1 0 -0.5236
          children [
            USE DS
          ]
          name "ds_right"
          lookupTable [
            0 0 0
            0.3 1000 0
          ]
        }
        Camera {
          translation -0.1 -0.015 0
          rotation 0 1 0 3.14159
          children [
            USE DS
          ]
          name "camera_left"
          fieldOfView 0.7
          width 1
          height 1
          far 0.1
        }
        Camera {
          translation -0.05 -0.015 0
          rotation 0 1 0 3.14159
          children [
            USE DS
          ]
          name "camera_right"
          fieldOfView 0.7
          width 1
          height 1
          far 0.1
        }
        Emitter {
          translation -0.075 -0.015 0
        }
        Receiver {
          translation -0.075 -0.015 0
        }
        Compass {
          translation -0.075 -0.015 0
          rotation 0 1 0 -1.57
        }
        GPS {
          translation -0.075 -0.015 0
        }
      ]
    }
  ]
  name "HungryHippo1"
  boundingObject USE BODY
  physics Physics {
  }
  controller "pre_planned_path"
}
Robot {
  translation 0.975061 0.05 -0.768389
  rotation 0 1 0 -1.57
  children [
    Solid {
      translation 0 -0.03 -0.0665
      children [
        Shape {
          appearance PBRAppearance {
            baseColor 0 0 0
          }
          geometry DEF CASTOR_BALL Sphere {
            radius 0.01
          }
        }
      ]
      name "solid(2)"
      contactMaterial "slippy"
      boundingObject USE CASTOR_BALL
      physics Physics {
      }
    }
    DEF BODY Shape {
      appearance PBRAppearance {
        baseColor 1 0 0
        metalness 0
      }
      geometry Box {
        size 0.15 0.065 0.173
      }
    }
    Transform {
      translation 0.075 0 0.0865
      children [
        DEF WHEEL1 HingeJoint {
          jointParameters HingeJointParameters {
            anchor 0.015 -0.005 -0.04
          }
          device [
            RotationalMotor {
              name "wheel1"
              maxTorque 100
            }
          ]
          endPoint Solid {
            translation 0.015 -0.005 -0.04
            rotation 0 0 0.9999999999999999 1.5707953071884027
            children [
              DEF WHEEL Shape {
                appearance PBRAppearance {
                }
                geometry Cylinder {
                  height 0.03
                  radius 0.035
                }
              }
            ]
            boundingObject USE WHEEL
            physics Physics {
            }
          }
        }
        DEF WHEEL2 HingeJoint {
          jointParameters HingeJointParameters {
            anchor -0.165 -0.005 -0.04
          }
          device [
            RotationalMotor {
              name "wheel2"
              maxTorque 100
            }
          ]
          endPoint Solid {
            translation -0.165 -0.005 -0.04
            rotation 0 0 1 1.57
            children [
              USE WHEEL
            ]
            name "solid(1)"
            boundingObject USE WHEEL
            physics Physics {
            }
          }
        }
        Solid {
          translation -0.006 -0.01 0.04
          children [
            DEF ARM Shape {
              appearance PBRAppearance {
              }
              geometry Box {
                size 0.012 0.05 0.08
              }
            }
          ]
          name "solid(3)"
          boundingObject USE ARM
          physics Physics {
          }
        }
        Solid {
          translation -0.144 -0.01 0.04
          children [
            USE ARM
          ]
          name "solid(4)"
          boundingObject USE ARM
          physics Physics {
          }
        }
        Solid {
          translation -0.075 0.015 0.04
          children [
            DEF LID Shape {
              appearance PBRAppearance {
              }
              geometry Box {
                size 0.126 0.001 0.08
              }
            }
          ]
          name "solid(5)"
          boundingObject USE LID
          physics Physics {
          }
        }
        DistanceSensor {
          translation -0.001 -0.015 0.08
          rotation 0 1 0 -2.61799
          children [
            DEF DS Shape {
              appearance PBRAppearance {
                baseColor 0 0 0
                metalness 0
              }
              geometry Box {
                size 0.01 0.01 0.01
              }
            }
          ]
          name "ds_left"
          lookupTable [
            0 0 0
            0.3 1000 0
          ]
        }
        DistanceSensor {
          translation -0.149 -0.015 0.08
          rotation 0 1 0 -0.5236
          children [
            USE DS
          ]
          name "ds_right"
          lookupTable [
            0 0 0
            0.3 1000 0
          ]
        }
        Camera {
          translation -0.075 -0.015 0
          rotation 0 1 0 3.14159
          children [
            USE DS
          ]
          width 1
          height 1
          far 0.1
        }
        Emitter {
          translation -0.075 -0.015 0
        }
        Receiver {
          translation -0.075 -0.015 0
        }
        Compass {
          translation -0.075 -0.015 0
          rotation 0 1 0 -1.57
        }
        GPS {
          translation -0.075 -0.015 0
        }
      ]
    }
  ]
  name "robotv2(1)"
  boundingObject USE BODY
  physics Physics {
  }
  controller ""
}
Robot {
  translation 1 0.05 -1
  rotation 0 1 0 -1.57
  children [
    Solid {
      translation 0 -0.03 -0.0665
      children [
        Shape {
          appearance PBRAppearance {
            baseColor 0 0 0
          }
          geometry DEF CASTOR_BALL Sphere {
            radius 0.01
          }
        }
      ]
      name "solid(2)"
      contactMaterial "slippy"
      boundingObject USE CASTOR_BALL
      physics Physics {
      }
    }
    DEF BODY Shape {
      appearance PBRAppearance {
        baseColor 0 0 1
        metalness 0
      }
      geometry Box {
        size 0.15 0.065 0.173
      }
    }
    Transform {
      translation 0.075 0 0.0865
      children [
        DEF WHEEL1 HingeJoint {
          jointParameters HingeJointParameters {
            anchor 0.015 -0.005 -0.04
          }
          device [
            RotationalMotor {
              name "wheel1"
              maxTorque 100
            }
          ]
          endPoint Solid {
            translation 0.015 -0.005 -0.04
            rotation 0 0 0.9999999999999999 1.5707953071884027
            children [
              DEF WHEEL Shape {
                appearance PBRAppearance {
                }
                geometry Cylinder {
                  height 0.03
                  radius 0.035
                }
              }
            ]
            boundingObject USE WHEEL
            physics Physics {
            }
          }
        }
        DEF WHEEL2 HingeJoint {
          jointParameters HingeJointParameters {
            anchor -0.165 -0.005 -0.04
          }
          device [
            RotationalMotor {
              name "wheel2"
              maxTorque 100
            }
          ]
          endPoint Solid {
            translation -0.165 -0.005 -0.04
            rotation 0 0 1 1.57
            children [
              USE WHEEL
            ]
            name "solid(1)"
            boundingObject USE WHEEL
            physics Physics {
            }
          }
        }
        Solid {
          translation -0.006 -0.01 0.04
          children [
            DEF ARM Shape {
              appearance PBRAppearance {
              }
              geometry Box {
                size 0.012 0.05 0.08
              }
            }
          ]
          name "solid(3)"
          boundingObject USE ARM
          physics Physics {
          }
        }
        Solid {
          translation -0.144 -0.01 0.04
          children [
            USE ARM
          ]
          name "solid(4)"
          boundingObject USE ARM
          physics Physics {
          }
        }
        Solid {
          translation -0.075 0.015 0.04
          children [
            DEF LID Shape {
              appearance PBRAppearance {
              }
              geometry Box {
                size 0.126 0.001 0.08
              }
            }
          ]
          name "solid(5)"
          boundingObject USE LID
          physics Physics {
          }
        }
        DistanceSensor {
          translation -0.001 -0.015 0.08
          rotation 0 1 0 -2.61799
          children [
            DEF DS Shape {
              appearance PBRAppearance {
                baseColor 0 0 0
                metalness 0
              }
              geometry Box {
                size 0.01 0.01 0.01
              }
            }
          ]
          name "ds_left"
          lookupTable [
            0 0 0
            0.3 1000 0
          ]
        }
        DistanceSensor {
          translation -0.149 -0.015 0.08
          rotation 0 1 0 -0.5236
          children [
            USE DS
          ]
          name "ds_right"
          lookupTable [
            0 0 0
            0.3 1000 0
          ]
        }
        Camera {
          translation -0.075 -0.015 0
          rotation 0 1 0 3.14159
          children [
            USE DS
          ]
          width 1
          height 1
          far 0.1
        }
        Emitter {
          translation -0.075 -0.015 0
        }
        Receiver {
          translation -0.075 -0.015 0
        }
        Compass {
          translation -0.075 -0.015 0
          rotation 0 1 0 -1.57
        }
        GPS {
          translation -0.075 -0.015 0
        }
      ]
    }
  ]
  name "robotv2(2)"
  boundingObject USE BODY
  physics Physics {
  }
  controller ""
}
