#VRML_SIM R2021a utf8
WorldInfo {
  basicTimeStep 16
  coordinateSystem "NUE"
  contactProperties [
    ContactProperties {
      material2 "slippy"
      coulombFriction [
        0
      ]
    }
    ContactProperties {
      material2 "block"
      coulombFriction [
        0.01
      ]
    }
  ]
}
Viewpoint {
  orientation -0.49390154358785954 -0.7279887956444521 -0.4754929848669381 1.9178374851359834
  position -2.37801650441923 6.158332017625043 -0.21046630682110706
}
TexturedBackground {
}
TexturedBackgroundLight {
}
Floor {
  size 2.4 2.4
  appearance Asphalt {
  }
}
DEF Block_R1 Solid {
  translation -0.300562 0.05 0.521295
  children [
    DEF BOX_R Shape {
      appearance PBRAppearance {
        baseColor 1 0 0
        metalness 0
      }
      geometry Box {
        size 0.05 0.05 0.05
      }
    }
  ]
  name "solid(4)"
  contactMaterial "box"
  boundingObject USE BOX_R
  physics Physics {
  }
}
DEF Block_R2 Solid {
  translation 0.107935 0.05 -0.979738
  children [
    DEF BOX_R Shape {
      appearance PBRAppearance {
        baseColor 1 0 0
        metalness 0
      }
      geometry Box {
        size 0.05 0.05 0.05
      }
    }
  ]
  name "solid(13)"
  boundingObject USE BOX_R
  physics Physics {
  }
}
DEF Block_R3 Solid {
  translation 0.499032 0.05 0.992651
  rotation 0 1 0 -0.785395307179586
  children [
    USE BOX_R
  ]
  name "solid(12)"
  boundingObject USE BOX_R
  physics Physics {
  }
}
DEF Block_R4 Solid {
  translation -0.811234 0.05 -1.02737
  rotation 0 1 0 1.309
  children [
    USE BOX_R
  ]
  name "solid(7)"
  boundingObject USE BOX_R
  physics Physics {
  }
  recognitionColors [
    1 0 0
  ]
}
DEF Block_B1 Solid {
  translation 0.605228 0.05 -0.34396
  rotation 0 1 0 1.0472
  children [
    DEF BOX_B Shape {
      appearance PBRAppearance {
        baseColor 0 0 1
        metalness 0
      }
      geometry Box {
        size 0.05 0.05 0.05
      }
    }
  ]
  name "solid(8)"
  boundingObject USE BOX_B
  physics Physics {
  }
}
DEF Block_B2 Solid {
  translation -0.872699 0.05 0.902069
  children [
    USE BOX_B
  ]
  name "solid(9)"
  boundingObject USE BOX_B
  physics Physics {
  }
}
DEF Block_B3 Solid {
  translation -0.751855 0.05 0.417004
  children [
    USE BOX_B
  ]
  name "solid(10)"
  boundingObject USE BOX_B
  physics Physics {
  }
}
DEF Block_B4 Solid {
  translation -0.446976 0.05 -0.568807
  children [
    USE BOX_B
  ]
  name "solid(11)"
  boundingObject USE BOX_B
  physics Physics {
  }
}
DEF Floor_colour Solid {
  translation 1 0.0001 1
  children [
    Shape {
      appearance PBRAppearance {
        baseColor 1 0 0
      }
      geometry Plane {
        size 0.4 0.4
      }
    }
  ]
  name "solid(6)"
}
DEF Floor_colour Solid {
  translation 1 0.0001 -1
  children [
    Shape {
      appearance PBRAppearance {
        baseColor 0 0 1
      }
      geometry Plane {
        size 0.4 0.4
      }
    }
  ]
  name "solid(5)"
}
DEF WALL_1 Solid {
  translation 1.2 0.05 0
  children [
    DEF WALL_SHAPE Shape {
      appearance PBRAppearance {
        baseColor 0 0.333333 0
        roughness 1
        metalness 0
      }
      geometry Box {
        size 0.02 0.1 2.38
      }
    }
  ]
  boundingObject USE WALL_SHAPE
}
DEF WALL_2 Solid {
  translation -1.2 0.05 0
  children [
    USE WALL_SHAPE
  ]
  name "solid(1)"
  boundingObject USE WALL_SHAPE
}
DEF WALL_3 Solid {
  translation 0 0.05 -1.2
  rotation 0 1 0 1.5708
  children [
    USE WALL_SHAPE
  ]
  name "solid(2)"
  boundingObject USE WALL_SHAPE
}
DEF WALL_4 Solid {
  translation 0 0.05 1.2
  rotation 0 1 0 1.5708
  children [
    USE WALL_SHAPE
  ]
  name "solid(3)"
  boundingObject USE WALL_SHAPE
}
Robot {
  translation 1 0.05 -1
  rotation 0 1 0 -1.57
  children [
    Solid {
      translation 0 -0.03 -0.0665
      children [
        Shape {
          appearance PBRAppearance {
            baseColor 0 0 0
          }
          geometry DEF CASTOR_BALL Sphere {
            radius 0.01
          }
        }
      ]
      name "solid(2)"
      contactMaterial "slippy"
      boundingObject USE CASTOR_BALL
      physics Physics {
      }
    }
    DEF BODY Shape {
      appearance PBRAppearance {
        baseColor 0 0.5 1
        metalness 0
      }
      geometry Box {
        size 0.15 0.065 0.173
      }
    }
    Transform {
      translation 0.075 0 0.0865
      children [
        DEF WHEEL1 HingeJoint {
          jointParameters HingeJointParameters {
            anchor 0.015 -0.005 -0.04
          }
          device [
            RotationalMotor {
              name "wheel1"
              maxTorque 100
            }
          ]
          endPoint Solid {
            translation 0.015000000000000013 -0.005000000000000012 -0.040000000000000036
            rotation 7.850466295613127e-17 3.9252331478065635e-16 0.9999999999999999 1.5707953071883962
            children [
              DEF WHEEL Shape {
                appearance PBRAppearance {
                }
                geometry Cylinder {
                  height 0.03
                  radius 0.035
                }
              }
            ]
            boundingObject USE WHEEL
            physics Physics {
            }
          }
        }
        DEF WHEEL2 HingeJoint {
          jointParameters HingeJointParameters {
            anchor -0.165 -0.005 -0.04
          }
          device [
            RotationalMotor {
              name "wheel2"
              maxTorque 100
            }
          ]
          endPoint Solid {
            translation -0.16500000000000015 -0.0049999999999999715 -0.039999999999999925
            rotation 2.0419333812578985e-15 -7.853589927914994e-17 1 1.5699999999999965
            children [
              USE WHEEL
            ]
            name "solid(1)"
            boundingObject USE WHEEL
            physics Physics {
            }
          }
        }
        Solid {
          translation -0.006 -0.01 0.04
          children [
            DEF ARM Shape {
              appearance PBRAppearance {
              }
              geometry Box {
                size 0.012 0.05 0.08
              }
            }
          ]
          name "solid(3)"
          boundingObject USE ARM
          physics Physics {
          }
        }
        Solid {
          translation -0.144 -0.01 0.04
          children [
            USE ARM
          ]
          name "solid(4)"
          boundingObject USE ARM
          physics Physics {
          }
        }
        Solid {
          translation -0.075 0.015 0.04
          children [
            DEF LID Shape {
              appearance PBRAppearance {
              }
              geometry Box {
                size 0.126 0.001 0.08
              }
            }
          ]
          name "solid(5)"
          boundingObject USE LID
          physics Physics {
          }
        }
        DistanceSensor {
          translation -0.001 -0.015 0.08
          rotation 0 1 0 -2.61799
          children [
            DEF DS Shape {
              appearance PBRAppearance {
                baseColor 0 0 0
                metalness 0
              }
              geometry Box {
                size 0.01 0.01 0.01
              }
            }
          ]
          name "ds_left"
          lookupTable [
            0 0 0
            0.3 1000 0
          ]
        }
        DistanceSensor {
          translation -0.149 -0.015 0.08
          rotation 0 1 0 -0.5236
          children [
            USE DS
          ]
          name "ds_right"
          lookupTable [
            0 0 0
            0.3 1000 0
          ]
        }
        Camera {
          translation -0.1 -0.015 0
          rotation 0 1 0 3.14159
          children [
            USE DS
          ]
          name "camera_left"
          recognitionColors [
            0 0 0
          ]
          fieldOfView 0.7854
          width 1
          height 1
          far 0.1
        }
        Camera {
          translation -0.05 -0.015 0
          rotation 0 1 0 3.14159
          children [
            USE DS
          ]
          name "camera_right"
          recognitionColors [
            0 0 0
          ]
          fieldOfView 0.7854
          width 1
          height 1
          far 0.1
        }
        Emitter {
          translation -0.075 -0.015 0
        }
        Receiver {
          translation -0.075 -0.015 0
        }
        Compass {
          translation -0.075 -0.015 0
          rotation 0 1 0 -1.57
        }
        GPS {
          translation -0.075 -0.015 0
        }
      ]
    }
  ]
  name "HungryHippo2"
  boundingObject USE BODY
  physics Physics {
  }
  controller "blue_controller"
  controllerArgs [
    ""
  ]
}
Robot {
  translation 1 0.05 1
  rotation 0 1 0 -1.57
  children [
    Solid {
      translation 0 -0.03 -0.0665
      children [
        Shape {
          appearance PBRAppearance {
            baseColor 0 0 0
          }
          geometry DEF CASTOR_BALL Sphere {
            radius 0.01
          }
        }
      ]
      name "solid(2)"
      contactMaterial "slippy"
      boundingObject USE CASTOR_BALL
      physics Physics {
      }
    }
    DEF BODY Shape {
      appearance PBRAppearance {
        baseColor 1 0 0
        metalness 0
      }
      geometry Box {
        size 0.15 0.065 0.173
      }
    }
    Transform {
      translation 0.075 0 0.0865
      children [
        DEF WHEEL1 HingeJoint {
          jointParameters HingeJointParameters {
            anchor 0.015 -0.005 -0.04
          }
          device [
            RotationalMotor {
              name "wheel1"
              maxTorque 100
            }
          ]
          endPoint Solid {
            translation 0.01499999999999968 -0.004999999999999989 -0.040000000000000036
            rotation 7.065419666051875e-16 2.257009059988793e-16 0.9999999999999999 1.5707953071883796
            children [
              DEF WHEEL Shape {
                appearance PBRAppearance {
                }
                geometry Cylinder {
                  height 0.03
                  radius 0.035
                }
              }
            ]
            boundingObject USE WHEEL
            physics Physics {
            }
          }
        }
        DEF WHEEL2 HingeJoint {
          jointParameters HingeJointParameters {
            anchor -0.165 -0.005 -0.04
          }
          device [
            RotationalMotor {
              name "wheel2"
              maxTorque 100
            }
          ]
          endPoint Solid {
            translation -0.16500000000000015 -0.005000000000000021 -0.039999999999999925
            rotation -3.0629000718868525e-15 -1.2565743884664008e-15 1 1.5699999999999934
            children [
              USE WHEEL
            ]
            name "solid(1)"
            boundingObject USE WHEEL
            physics Physics {
            }
          }
        }
        Solid {
          translation -0.006 -0.01 0.04
          children [
            DEF ARM Shape {
              appearance PBRAppearance {
              }
              geometry Box {
                size 0.012 0.05 0.08
              }
            }
          ]
          name "solid(3)"
          boundingObject USE ARM
          physics Physics {
          }
        }
        Solid {
          translation -0.144 -0.01 0.04
          children [
            USE ARM
          ]
          name "solid(4)"
          boundingObject USE ARM
          physics Physics {
          }
        }
        Solid {
          translation -0.075 0.015 0.04
          children [
            DEF LID Shape {
              appearance PBRAppearance {
              }
              geometry Box {
                size 0.126 0.001 0.08
              }
            }
          ]
          name "solid(5)"
          boundingObject USE LID
          physics Physics {
          }
        }
        DistanceSensor {
          translation -0.001 -0.015 0.08
          rotation 0 1 0 -2.61799
          children [
            DEF DS Shape {
              appearance PBRAppearance {
                baseColor 0 0 0
                metalness 0
              }
              geometry Box {
                size 0.01 0.01 0.01
              }
            }
          ]
          name "ds_left"
          lookupTable [
            0 0 0
            0.3 1000 0
          ]
        }
        DistanceSensor {
          translation -0.149 -0.015 0.08
          rotation 0 1 0 -0.5236
          children [
            USE DS
          ]
          name "ds_right"
          lookupTable [
            0 0 0
            0.3 1000 0
          ]
        }
        Camera {
          translation -0.1 -0.015 0
          rotation 0 1 0 3.14159
          children [
            USE DS
          ]
          name "camera_left"
          fieldOfView 0.7
          width 1
          height 1
          far 0.1
        }
        Camera {
          translation -0.05 -0.015 0
          rotation 0 1 0 3.14159
          children [
            USE DS
          ]
          name "camera_right"
          fieldOfView 0.7
          width 1
          height 1
          far 0.1
        }
        Emitter {
          translation -0.075 -0.015 0
        }
        Receiver {
          translation -0.075 -0.015 0
        }
        Compass {
          translation -0.075 -0.015 0
          rotation 0 1 0 -1.57
        }
        GPS {
          translation -0.075 -0.015 0
        }
      ]
    }
  ]
  name "HungryHippo1"
  boundingObject USE BODY
  physics Physics {
  }
  controller "pre_planned_path"
}
Robot {
  translation 0.73653 0.05 -1.75148
  rotation 0 1 0 -1.57
  children [
    Solid {
      translation 0 -0.03 -0.0665
      children [
        Shape {
          appearance PBRAppearance {
            baseColor 0 0 0
          }
          geometry DEF CASTOR_BALL Sphere {
            radius 0.01
          }
        }
      ]
      name "solid(2)"
      contactMaterial "slippy"
      boundingObject USE CASTOR_BALL
      physics Physics {
      }
    }
    DEF BODY Shape {
      appearance PBRAppearance {
        baseColor 1 0 0
        metalness 0
      }
      geometry Box {
        size 0.15 0.065 0.173
      }
    }
    Transform {
      translation 0.075 0 0.0865
      children [
        DEF WHEEL1 HingeJoint {
          jointParameters HingeJointParameters {
            anchor 0.015 -0.005 -0.04
          }
          device [
            RotationalMotor {
              name "wheel1"
              maxTorque 100
            }
          ]
          endPoint Solid {
            translation 0.015 -0.005 -0.04
            rotation 0 0 0.9999999999999999 1.5707953071884027
            children [
              DEF WHEEL Shape {
                appearance PBRAppearance {
                }
                geometry Cylinder {
                  height 0.03
                  radius 0.035
                }
              }
            ]
            boundingObject USE WHEEL
            physics Physics {
            }
          }
        }
        DEF WHEEL2 HingeJoint {
          jointParameters HingeJointParameters {
            anchor -0.165 -0.005 -0.04
          }
          device [
            RotationalMotor {
              name "wheel2"
              maxTorque 100
            }
          ]
          endPoint Solid {
            translation -0.165 -0.005 -0.04
            rotation 0 0 1 1.57
            children [
              USE WHEEL
            ]
            name "solid(1)"
            boundingObject USE WHEEL
            physics Physics {
            }
          }
        }
        Solid {
          translation -0.006 -0.01 0.04
          children [
            DEF ARM Shape {
              appearance PBRAppearance {
              }
              geometry Box {
                size 0.012 0.05 0.08
              }
            }
          ]
          name "solid(3)"
          boundingObject USE ARM
          physics Physics {
          }
        }
        Solid {
          translation -0.144 -0.01 0.04
          children [
            USE ARM
          ]
          name "solid(4)"
          boundingObject USE ARM
          physics Physics {
          }
        }
        Solid {
          translation -0.075 0.015 0.04
          children [
            DEF LID Shape {
              appearance PBRAppearance {
              }
              geometry Box {
                size 0.126 0.001 0.08
              }
            }
          ]
          name "solid(5)"
          boundingObject USE LID
          physics Physics {
          }
        }
        DistanceSensor {
          translation -0.001 -0.015 0.08
          rotation 0 1 0 -2.61799
          children [
            DEF DS Shape {
              appearance PBRAppearance {
                baseColor 0 0 0
                metalness 0
              }
              geometry Box {
                size 0.01 0.01 0.01
              }
            }
          ]
          name "ds_left"
          lookupTable [
            0 0 0
            0.3 1000 0
          ]
        }
        DistanceSensor {
          translation -0.149 -0.015 0.08
          rotation 0 1 0 -0.5236
          children [
            USE DS
          ]
          name "ds_right"
          lookupTable [
            0 0 0
            0.3 1000 0
          ]
        }
        Camera {
          translation -0.075 -0.015 0
          rotation 0 1 0 3.14159
          children [
            USE DS
          ]
          width 1
          height 1
          far 0.1
        }
        Emitter {
          translation -0.075 -0.015 0
        }
        Receiver {
          translation -0.075 -0.015 0
        }
        Compass {
          translation -0.075 -0.015 0
          rotation 0 1 0 -1.57
        }
        GPS {
          translation -0.075 -0.015 0
        }
      ]
    }
  ]
  name "robotv2(1)"
  boundingObject USE BODY
  physics Physics {
  }
  controller ""
}
Robot {
  translation 0.294068 0.05 -1.77531
  rotation 0 1 0 -1.57
  children [
    Solid {
      translation 0 -0.03 -0.0665
      children [
        Shape {
          appearance PBRAppearance {
            baseColor 0 0 0
          }
          geometry DEF CASTOR_BALL Sphere {
            radius 0.01
          }
        }
      ]
      name "solid(2)"
      contactMaterial "slippy"
      boundingObject USE CASTOR_BALL
      physics Physics {
      }
    }
    DEF BODY Shape {
      appearance PBRAppearance {
        baseColor 0 0 1
        metalness 0
      }
      geometry Box {
        size 0.15 0.065 0.173
      }
    }
    Transform {
      translation 0.075 0 0.0865
      children [
        DEF WHEEL1 HingeJoint {
          jointParameters HingeJointParameters {
            anchor 0.015 -0.005 -0.04
          }
          device [
            RotationalMotor {
              name "wheel1"
              maxTorque 100
            }
          ]
          endPoint Solid {
            translation 0.015 -0.005 -0.04
            rotation 0 0 0.9999999999999999 1.5707953071884027
            children [
              DEF WHEEL Shape {
                appearance PBRAppearance {
                }
                geometry Cylinder {
                  height 0.03
                  radius 0.035
                }
              }
            ]
            boundingObject USE WHEEL
            physics Physics {
            }
          }
        }
        DEF WHEEL2 HingeJoint {
          jointParameters HingeJointParameters {
            anchor -0.165 -0.005 -0.04
          }
          device [
            RotationalMotor {
              name "wheel2"
              maxTorque 100
            }
          ]
          endPoint Solid {
            translation -0.165 -0.005 -0.04
            rotation 0 0 1 1.57
            children [
              USE WHEEL
            ]
            name "solid(1)"
            boundingObject USE WHEEL
            physics Physics {
            }
          }
        }
        Solid {
          translation -0.006 -0.01 0.04
          children [
            DEF ARM Shape {
              appearance PBRAppearance {
              }
              geometry Box {
                size 0.012 0.05 0.08
              }
            }
          ]
          name "solid(3)"
          boundingObject USE ARM
          physics Physics {
          }
        }
        Solid {
          translation -0.144 -0.01 0.04
          children [
            USE ARM
          ]
          name "solid(4)"
          boundingObject USE ARM
          physics Physics {
          }
        }
        Solid {
          translation -0.075 0.015 0.04
          children [
            DEF LID Shape {
              appearance PBRAppearance {
              }
              geometry Box {
                size 0.126 0.001 0.08
              }
            }
          ]
          name "solid(5)"
          boundingObject USE LID
          physics Physics {
          }
        }
        DistanceSensor {
          translation -0.001 -0.015 0.08
          rotation 0 1 0 -2.61799
          children [
            DEF DS Shape {
              appearance PBRAppearance {
                baseColor 0 0 0
                metalness 0
              }
              geometry Box {
                size 0.01 0.01 0.01
              }
            }
          ]
          name "ds_left"
          lookupTable [
            0 0 0
            0.3 1000 0
          ]
        }
        DistanceSensor {
          translation -0.149 -0.015 0.08
          rotation 0 1 0 -0.5236
          children [
            USE DS
          ]
          name "ds_right"
          lookupTable [
            0 0 0
            0.3 1000 0
          ]
        }
        Camera {
          translation -0.075 -0.015 0
          rotation 0 1 0 3.14159
          children [
            USE DS
          ]
          width 1
          height 1
          far 0.1
        }
        Emitter {
          translation -0.075 -0.015 0
        }
        Receiver {
          translation -0.075 -0.015 0
        }
        Compass {
          translation -0.075 -0.015 0
          rotation 0 1 0 -1.57
        }
        GPS {
          translation -0.075 -0.015 0
        }
      ]
    }
  ]
  name "robotv2(2)"
  boundingObject USE BODY
  physics Physics {
  }
  controller ""
}
